  File "main.py", line 51, in <module>
    model_trainer.main()
  File "d:\text-summarization-nlp-project-main\src\textSummarizer\pipeline\stage_04_model_trainer.py", line 14, in main
    model_trainer_config.train()
  File "d:\text-summarization-nlp-project-main\src\textSummarizer\conponents\model_trainer.py", line 34, in train
    trainer_args = TrainingArguments(
  File "<string>", line 111, in __init__
  File "D:\Text-Summarization-NLP-Project-main\text\lib\site-packages\transformers\training_args.py", line 1372, in __post_init__
    and (self.device.type != "cuda")
  File "D:\Text-Summarization-NLP-Project-main\text\lib\site-packages\transformers\training_args.py", line 1795, in device
    return self._setup_devices
  File "D:\Text-Summarization-NLP-Project-main\text\lib\site-packages\transformers\utils\generic.py", line 54, in __get__
    cached = self.fget(obj)
  File "D:\Text-Summarization-NLP-Project-main\text\lib\site-packages\transformers\training_args.py", line 1716, in _setup_devices
    raise ImportError(
ImportError: Using the `Trainer` with `PyTorch` requires `accelerate>=0.20.1`: Please run `pip install transformers[torch]` or `pip install accelerate -U`
[2023-07-19 21:42:46,492: INFO: common: yaml file: config\config.yaml loaded successfully]
[2023-07-19 21:42:46,500: INFO: common: yaml file: params.yaml loaded successfully]
[2023-07-19 21:42:46,500: INFO: common: created directory at: artifacts]
[2023-07-19 21:42:46,500: INFO: common: created directory at: artifacts/model_evaluation]
[2023-07-19 21:42:46,502: ERROR: h11_impl: Exception in ASGI application
]
Traceback (most recent call last):
  File "D:\Text-Summarization-NLP-Project-main\text\lib\site-packages\uvicorn\protocols\http\h11_impl.py", line 404, in run_asgi
    result = await app(  # type: ignore[func-returns-value]
  File "D:\Text-Summarization-NLP-Project-main\text\lib\site-packages\uvicorn\middleware\proxy_headers.py", line 78, in __call__
    return await self.app(scope, receive, send)
  File "D:\Text-Summarization-NLP-Project-main\text\lib\site-packages\fastapi\applications.py", line 269, in __call__
    await super().__call__(scope, receive, send)
  File "D:\Text-Summarization-NLP-Project-main\text\lib\site-packages\starlette\applications.py", line 124, in __call__
    await self.middleware_stack(scope, receive, send)
  File "D:\Text-Summarization-NLP-Project-main\text\lib\site-packages\starlette\middleware\errors.py", line 184, in __call__
    raise exc
  File "D:\Text-Summarization-NLP-Project-main\text\lib\site-packages\starlette\middleware\errors.py", line 162, in __call__
    await self.app(scope, receive, _send)
  File "D:\Text-Summarization-NLP-Project-main\text\lib\site-packages\starlette\exceptions.py", line 93, in __call__
    raise exc
  File "D:\Text-Summarization-NLP-Project-main\text\lib\site-packages\starlette\exceptions.py", line 82, in __call__
    await self.app(scope, receive, sender)
  File "D:\Text-Summarization-NLP-Project-main\text\lib\site-packages\fastapi\middleware\asyncexitstack.py", line 21, in __call__
    raise e
  File "D:\Text-Summarization-NLP-Project-main\text\lib\site-packages\fastapi\middleware\asyncexitstack.py", line 18, in __call__
    await self.app(scope, receive, send)
  File "D:\Text-Summarization-NLP-Project-main\text\lib\site-packages\starlette\routing.py", line 670, in __call__
    await route.handle(scope, receive, send)
  File "D:\Text-Summarization-NLP-Project-main\text\lib\site-packages\starlette\routing.py", line 266, in handle
    await self.app(scope, receive, send)
  File "D:\Text-Summarization-NLP-Project-main\text\lib\site-packages\starlette\routing.py", line 65, in app
    response = await func(request)
  File "D:\Text-Summarization-NLP-Project-main\text\lib\site-packages\fastapi\routing.py", line 227, in app
    raw_response = await run_endpoint_function(
  File "D:\Text-Summarization-NLP-Project-main\text\lib\site-packages\fastapi\routing.py", line 160, in run_endpoint_function
    return await dependant.call(**values)
  File "app.py", line 41, in predict_route
    raise e
  File "app.py", line 38, in predict_route
    text = obj.predict(text)
  File "d:\text-summarization-nlp-project-main\src\textSummarizer\pipeline\prediction.py", line 13, in predict
    tokenizer = AutoTokenizer.from_pretrained(self.config.tokenizer_path)
  File "D:\Text-Summarization-NLP-Project-main\text\lib\site-packages\transformers\models\auto\tokenization_auto.py", line 652, in from_pretrained
    tokenizer_config = get_tokenizer_config(pretrained_model_name_or_path, **kwargs)
  File "D:\Text-Summarization-NLP-Project-main\text\lib\site-packages\transformers\models\auto\tokenization_auto.py", line 496, in get_tokenizer_config
    resolved_config_file = cached_file(
  File "D:\Text-Summarization-NLP-Project-main\text\lib\site-packages\transformers\utils\hub.py", line 417, in cached_file
    resolved_file = hf_hub_download(
  File "D:\Text-Summarization-NLP-Project-main\text\lib\site-packages\huggingface_hub\utils\_validators.py", line 110, in _inner_fn
    validate_repo_id(arg_value)
  File "D:\Text-Summarization-NLP-Project-main\text\lib\site-packages\huggingface_hub\utils\_validators.py", line 158, in validate_repo_id
    raise HFValidationError(
huggingface_hub.utils._validators.HFValidationError: Repo id must be in the form 'repo_name' or 'namespace/repo_name': 'artifacts/model_trainer/tokenizer'. Use `repo_type` argument if needed.
[2023-07-19 21:42:56,056: INFO: common: yaml file: config\config.yaml loaded successfully]
[2023-07-19 21:42:56,057: INFO: common: yaml file: params.yaml loaded successfully]
[2023-07-19 21:42:56,058: INFO: common: created directory at: artifacts]
[2023-07-19 21:42:56,059: INFO: common: created directory at: artifacts/model_evaluation]
[2023-07-19 21:42:56,059: ERROR: h11_impl: Exception in ASGI application
]
Traceback (most recent call last):
  File "D:\Text-Summarization-NLP-Project-main\text\lib\site-packages\uvicorn\protocols\http\h11_impl.py", line 404, in run_asgi
    result = await app(  # type: ignore[func-returns-value]
  File "D:\Text-Summarization-NLP-Project-main\text\lib\site-packages\uvicorn\middleware\proxy_headers.py", line 78, in __call__
    return await self.app(scope, receive, send)
  File "D:\Text-Summarization-NLP-Project-main\text\lib\site-packages\fastapi\applications.py", line 269, in __call__
    await super().__call__(scope, receive, send)
  File "D:\Text-Summarization-NLP-Project-main\text\lib\site-packages\starlette\applications.py", line 124, in __call__
    await self.middleware_stack(scope, receive, send)
  File "D:\Text-Summarization-NLP-Project-main\text\lib\site-packages\starlette\middleware\errors.py", line 184, in __call__
    raise exc
  File "D:\Text-Summarization-NLP-Project-main\text\lib\site-packages\starlette\middleware\errors.py", line 162, in __call__
    await self.app(scope, receive, _send)
  File "D:\Text-Summarization-NLP-Project-main\text\lib\site-packages\starlette\exceptions.py", line 93, in __call__
    raise exc
  File "D:\Text-Summarization-NLP-Project-main\text\lib\site-packages\starlette\exceptions.py", line 82, in __call__
    await self.app(scope, receive, sender)
  File "D:\Text-Summarization-NLP-Project-main\text\lib\site-packages\fastapi\middleware\asyncexitstack.py", line 21, in __call__
    raise e
  File "D:\Text-Summarization-NLP-Project-main\text\lib\site-packages\fastapi\middleware\asyncexitstack.py", line 18, in __call__
    await self.app(scope, receive, send)
  File "D:\Text-Summarization-NLP-Project-main\text\lib\site-packages\starlette\routing.py", line 670, in __call__
    await route.handle(scope, receive, send)
  File "D:\Text-Summarization-NLP-Project-main\text\lib\site-packages\starlette\routing.py", line 266, in handle
    await self.app(scope, receive, send)
  File "D:\Text-Summarization-NLP-Project-main\text\lib\site-packages\starlette\routing.py", line 65, in app
    response = await func(request)
  File "D:\Text-Summarization-NLP-Project-main\text\lib\site-packages\fastapi\routing.py", line 227, in app
    raw_response = await run_endpoint_function(
  File "D:\Text-Summarization-NLP-Project-main\text\lib\site-packages\fastapi\routing.py", line 160, in run_endpoint_function
    return await dependant.call(**values)
  File "app.py", line 41, in predict_route
    raise e
  File "app.py", line 38, in predict_route
    text = obj.predict(text)
  File "d:\text-summarization-nlp-project-main\src\textSummarizer\pipeline\prediction.py", line 13, in predict
    tokenizer = AutoTokenizer.from_pretrained(self.config.tokenizer_path)
  File "D:\Text-Summarization-NLP-Project-main\text\lib\site-packages\transformers\models\auto\tokenization_auto.py", line 652, in from_pretrained
    tokenizer_config = get_tokenizer_config(pretrained_model_name_or_path, **kwargs)
  File "D:\Text-Summarization-NLP-Project-main\text\lib\site-packages\transformers\models\auto\tokenization_auto.py", line 496, in get_tokenizer_config
    resolved_config_file = cached_file(
  File "D:\Text-Summarization-NLP-Project-main\text\lib\site-packages\transformers\utils\hub.py", line 417, in cached_file
    resolved_file = hf_hub_download(
  File "D:\Text-Summarization-NLP-Project-main\text\lib\site-packages\huggingface_hub\utils\_validators.py", line 110, in _inner_fn
    validate_repo_id(arg_value)
  File "D:\Text-Summarization-NLP-Project-main\text\lib\site-packages\huggingface_hub\utils\_validators.py", line 158, in validate_repo_id
    raise HFValidationError(
huggingface_hub.utils._validators.HFValidationError: Repo id must be in the form 'repo_name' or 'namespace/repo_name': 'artifacts/model_trainer/tokenizer'. Use `repo_type` argument if needed.
[2023-07-19 21:44:49,278: INFO: server: Shutting down]
[2023-07-19 21:44:49,382: INFO: on: Waiting for application shutdown.]
[2023-07-19 21:44:49,382: INFO: on: Application shutdown complete.]
[2023-07-19 21:44:49,382: INFO: server: Finished server process [16800]]
[2024-01-02 12:52:31,790: INFO: server: Started server process [17036]]
[2024-01-02 12:52:31,791: INFO: on: Waiting for application startup.]
[2024-01-02 12:52:31,791: INFO: on: Application startup complete.]
[2024-01-02 12:52:31,792: INFO: server: Uvicorn running on http://0.0.0.0:8080 (Press CTRL+C to quit)]
[2024-01-02 12:55:30,833: INFO: common: yaml file: config\config.yaml loaded successfully]
[2024-01-02 12:55:30,878: INFO: common: yaml file: params.yaml loaded successfully]
[2024-01-02 12:55:30,880: INFO: common: created directory at: artifacts]
[2024-01-02 12:55:30,881: INFO: common: created directory at: artifacts/model_evaluation]
[2024-01-02 12:55:30,900: ERROR: h11_impl: Exception in ASGI application
]
Traceback (most recent call last):
  File "C:\Users\Kiran Aradhya\anaconda3\envs\textS1\lib\site-packages\transformers\utils\hub.py", line 389, in cached_file
    resolved_file = hf_hub_download(
  File "C:\Users\Kiran Aradhya\anaconda3\envs\textS1\lib\site-packages\huggingface_hub\utils\_validators.py", line 110, in _inner_fn
    validate_repo_id(arg_value)
  File "C:\Users\Kiran Aradhya\anaconda3\envs\textS1\lib\site-packages\huggingface_hub\utils\_validators.py", line 158, in validate_repo_id
    raise HFValidationError(
huggingface_hub.utils._validators.HFValidationError: Repo id must be in the form 'repo_name' or 'namespace/repo_name': 'artifacts/model_trainer/tokenizer'. Use `repo_type` argument if needed.

The above exception was the direct cause of the following exception:

Traceback (most recent call last):
  File "C:\Users\Kiran Aradhya\anaconda3\envs\textS1\lib\site-packages\uvicorn\protocols\http\h11_impl.py", line 404, in run_asgi
    result = await app(  # type: ignore[func-returns-value]
  File "C:\Users\Kiran Aradhya\anaconda3\envs\textS1\lib\site-packages\uvicorn\middleware\proxy_headers.py", line 78, in __call__
    return await self.app(scope, receive, send)
  File "C:\Users\Kiran Aradhya\anaconda3\envs\textS1\lib\site-packages\fastapi\applications.py", line 269, in __call__
    await super().__call__(scope, receive, send)
  File "C:\Users\Kiran Aradhya\anaconda3\envs\textS1\lib\site-packages\starlette\applications.py", line 124, in __call__
    await self.middleware_stack(scope, receive, send)
  File "C:\Users\Kiran Aradhya\anaconda3\envs\textS1\lib\site-packages\starlette\middleware\errors.py", line 184, in __call__
    raise exc
  File "C:\Users\Kiran Aradhya\anaconda3\envs\textS1\lib\site-packages\starlette\middleware\errors.py", line 162, in __call__
    await self.app(scope, receive, _send)
  File "C:\Users\Kiran Aradhya\anaconda3\envs\textS1\lib\site-packages\starlette\exceptions.py", line 93, in __call__
    raise exc
  File "C:\Users\Kiran Aradhya\anaconda3\envs\textS1\lib\site-packages\starlette\exceptions.py", line 82, in __call__
    await self.app(scope, receive, sender)
  File "C:\Users\Kiran Aradhya\anaconda3\envs\textS1\lib\site-packages\fastapi\middleware\asyncexitstack.py", line 21, in __call__
    raise e
  File "C:\Users\Kiran Aradhya\anaconda3\envs\textS1\lib\site-packages\fastapi\middleware\asyncexitstack.py", line 18, in __call__
    await self.app(scope, receive, send)
  File "C:\Users\Kiran Aradhya\anaconda3\envs\textS1\lib\site-packages\starlette\routing.py", line 670, in __call__
    await route.handle(scope, receive, send)
  File "C:\Users\Kiran Aradhya\anaconda3\envs\textS1\lib\site-packages\starlette\routing.py", line 266, in handle
    await self.app(scope, receive, send)
  File "C:\Users\Kiran Aradhya\anaconda3\envs\textS1\lib\site-packages\starlette\routing.py", line 65, in app
    response = await func(request)
  File "C:\Users\Kiran Aradhya\anaconda3\envs\textS1\lib\site-packages\fastapi\routing.py", line 227, in app
    raw_response = await run_endpoint_function(
  File "C:\Users\Kiran Aradhya\anaconda3\envs\textS1\lib\site-packages\fastapi\routing.py", line 160, in run_endpoint_function
    return await dependant.call(**values)
  File "app.py", line 41, in predict_route
    raise e
  File "app.py", line 38, in predict_route
    text = obj.predict(text)
  File "d:\text-summarizer-project\src\textSummarizer\pipeline\prediction.py", line 13, in predict
    tokenizer = AutoTokenizer.from_pretrained(self.config.tokenizer_path)
  File "C:\Users\Kiran Aradhya\anaconda3\envs\textS1\lib\site-packages\transformers\models\auto\tokenization_auto.py", line 737, in from_pretrained
    tokenizer_config = get_tokenizer_config(pretrained_model_name_or_path, **kwargs)
  File "C:\Users\Kiran Aradhya\anaconda3\envs\textS1\lib\site-packages\transformers\models\auto\tokenization_auto.py", line 569, in get_tokenizer_config
    resolved_config_file = cached_file(
  File "C:\Users\Kiran Aradhya\anaconda3\envs\textS1\lib\site-packages\transformers\utils\hub.py", line 454, in cached_file
    raise EnvironmentError(
OSError: Incorrect path_or_model_id: 'artifacts/model_trainer/tokenizer'. Please provide either the path to a local folder or the repo_id of a model on the Hub.
[2024-01-02 12:55:43,971: INFO: common: yaml file: config\config.yaml loaded successfully]
[2024-01-02 12:55:43,974: INFO: common: yaml file: params.yaml loaded successfully]
[2024-01-02 12:55:43,974: INFO: common: created directory at: artifacts]
[2024-01-02 12:55:43,975: INFO: common: created directory at: artifacts/model_evaluation]
[2024-01-02 12:55:43,976: ERROR: h11_impl: Exception in ASGI application
]
Traceback (most recent call last):
  File "C:\Users\Kiran Aradhya\anaconda3\envs\textS1\lib\site-packages\transformers\utils\hub.py", line 389, in cached_file
    resolved_file = hf_hub_download(
  File "C:\Users\Kiran Aradhya\anaconda3\envs\textS1\lib\site-packages\huggingface_hub\utils\_validators.py", line 110, in _inner_fn
    validate_repo_id(arg_value)
  File "C:\Users\Kiran Aradhya\anaconda3\envs\textS1\lib\site-packages\huggingface_hub\utils\_validators.py", line 158, in validate_repo_id
    raise HFValidationError(
huggingface_hub.utils._validators.HFValidationError: Repo id must be in the form 'repo_name' or 'namespace/repo_name': 'artifacts/model_trainer/tokenizer'. Use `repo_type` argument if needed.

The above exception was the direct cause of the following exception:

Traceback (most recent call last):
  File "C:\Users\Kiran Aradhya\anaconda3\envs\textS1\lib\site-packages\uvicorn\protocols\http\h11_impl.py", line 404, in run_asgi
    result = await app(  # type: ignore[func-returns-value]
  File "C:\Users\Kiran Aradhya\anaconda3\envs\textS1\lib\site-packages\uvicorn\middleware\proxy_headers.py", line 78, in __call__
    return await self.app(scope, receive, send)
  File "C:\Users\Kiran Aradhya\anaconda3\envs\textS1\lib\site-packages\fastapi\applications.py", line 269, in __call__
    await super().__call__(scope, receive, send)
  File "C:\Users\Kiran Aradhya\anaconda3\envs\textS1\lib\site-packages\starlette\applications.py", line 124, in __call__
    await self.middleware_stack(scope, receive, send)
  File "C:\Users\Kiran Aradhya\anaconda3\envs\textS1\lib\site-packages\starlette\middleware\errors.py", line 184, in __call__
    raise exc
  File "C:\Users\Kiran Aradhya\anaconda3\envs\textS1\lib\site-packages\starlette\middleware\errors.py", line 162, in __call__
    await self.app(scope, receive, _send)
  File "C:\Users\Kiran Aradhya\anaconda3\envs\textS1\lib\site-packages\starlette\exceptions.py", line 93, in __call__
    raise exc
  File "C:\Users\Kiran Aradhya\anaconda3\envs\textS1\lib\site-packages\starlette\exceptions.py", line 82, in __call__
    await self.app(scope, receive, sender)
  File "C:\Users\Kiran Aradhya\anaconda3\envs\textS1\lib\site-packages\fastapi\middleware\asyncexitstack.py", line 21, in __call__
    raise e
  File "C:\Users\Kiran Aradhya\anaconda3\envs\textS1\lib\site-packages\fastapi\middleware\asyncexitstack.py", line 18, in __call__
    await self.app(scope, receive, send)
  File "C:\Users\Kiran Aradhya\anaconda3\envs\textS1\lib\site-packages\starlette\routing.py", line 670, in __call__
    await route.handle(scope, receive, send)
  File "C:\Users\Kiran Aradhya\anaconda3\envs\textS1\lib\site-packages\starlette\routing.py", line 266, in handle
    await self.app(scope, receive, send)
  File "C:\Users\Kiran Aradhya\anaconda3\envs\textS1\lib\site-packages\starlette\routing.py", line 65, in app
    response = await func(request)
  File "C:\Users\Kiran Aradhya\anaconda3\envs\textS1\lib\site-packages\fastapi\routing.py", line 227, in app
    raw_response = await run_endpoint_function(
  File "C:\Users\Kiran Aradhya\anaconda3\envs\textS1\lib\site-packages\fastapi\routing.py", line 160, in run_endpoint_function
    return await dependant.call(**values)
  File "app.py", line 41, in predict_route
    raise e
  File "app.py", line 38, in predict_route
    text = obj.predict(text)
  File "d:\text-summarizer-project\src\textSummarizer\pipeline\prediction.py", line 13, in predict
    tokenizer = AutoTokenizer.from_pretrained(self.config.tokenizer_path)
  File "C:\Users\Kiran Aradhya\anaconda3\envs\textS1\lib\site-packages\transformers\models\auto\tokenization_auto.py", line 737, in from_pretrained
    tokenizer_config = get_tokenizer_config(pretrained_model_name_or_path, **kwargs)
  File "C:\Users\Kiran Aradhya\anaconda3\envs\textS1\lib\site-packages\transformers\models\auto\tokenization_auto.py", line 569, in get_tokenizer_config
    resolved_config_file = cached_file(
  File "C:\Users\Kiran Aradhya\anaconda3\envs\textS1\lib\site-packages\transformers\utils\hub.py", line 454, in cached_file
    raise EnvironmentError(
OSError: Incorrect path_or_model_id: 'artifacts/model_trainer/tokenizer'. Please provide either the path to a local folder or the repo_id of a model on the Hub.
[2024-01-02 12:56:26,674: INFO: config: PyTorch version 2.1.2 available.]
[2024-01-02 12:56:27,740: INFO: main: >>>>>> stage Data Ingestion stage started <<<<<<]
[2024-01-02 12:56:27,745: INFO: common: yaml file: config\config.yaml loaded successfully]
[2024-01-02 12:56:27,746: INFO: common: yaml file: params.yaml loaded successfully]
[2024-01-02 12:56:27,747: INFO: common: created directory at: artifacts]
[2024-01-02 12:56:27,747: INFO: common: created directory at: artifacts/data_ingestion]
[2024-01-02 12:56:27,747: INFO: data_ingestion: Downloading data from https://github.com/entbappy/Branching-tutorial/raw/master/summarizer-data.zip into file artifacts/data_ingestion/data.zip]
[2024-01-02 12:56:28,531: INFO: data_ingestion: Downloaded data from https://github.com/entbappy/Branching-tutorial/raw/master/summarizer-data.zip into file artifacts/data_ingestion/data.zip]
[2024-01-02 12:56:28,642: INFO: main: >>>>>> stage Data Ingestion stage completed <<<<<<

x==========x]
[2024-01-02 12:56:28,643: INFO: main: >>>>>> stage Data Validation stage started <<<<<<]
[2024-01-02 12:56:28,646: INFO: common: yaml file: config\config.yaml loaded successfully]
[2024-01-02 12:56:28,647: INFO: common: yaml file: params.yaml loaded successfully]
[2024-01-02 12:56:28,648: INFO: common: created directory at: artifacts]
[2024-01-02 12:56:28,648: INFO: common: created directory at: artifacts/data_validation]
[2024-01-02 12:56:28,649: ERROR: main: [WinError 3] The system cannot find the path specified: 'artifacts\\data_ingestion\\samsun\\samsum_dataset']
Traceback (most recent call last):
  File "main.py", line 26, in <module>
    data_validation.main()
  File "d:\text-summarizer-project\src\textSummarizer\pipeline\stage_02_data_validation.py", line 14, in main
    data_validation.validate_all_files_exist()
  File "d:\text-summarizer-project\src\textSummarizer\conponents\data_validation.py", line 30, in validate_all_files_exist
    raise e
  File "d:\text-summarizer-project\src\textSummarizer\conponents\data_validation.py", line 15, in validate_all_files_exist
    all_files = os.listdir(os.path.join("artifacts","data_ingestion","samsun","samsum_dataset"))
FileNotFoundError: [WinError 3] The system cannot find the path specified: 'artifacts\\data_ingestion\\samsun\\samsum_dataset'
[2024-01-02 12:57:17,298: INFO: common: yaml file: config\config.yaml loaded successfully]
[2024-01-02 12:57:17,300: INFO: common: yaml file: params.yaml loaded successfully]
[2024-01-02 12:57:17,301: INFO: common: created directory at: artifacts]
[2024-01-02 12:57:17,301: INFO: common: created directory at: artifacts/model_evaluation]
[2024-01-02 12:57:17,302: ERROR: h11_impl: Exception in ASGI application
]
Traceback (most recent call last):
  File "C:\Users\Kiran Aradhya\anaconda3\envs\textS1\lib\site-packages\transformers\utils\hub.py", line 389, in cached_file
    resolved_file = hf_hub_download(
  File "C:\Users\Kiran Aradhya\anaconda3\envs\textS1\lib\site-packages\huggingface_hub\utils\_validators.py", line 110, in _inner_fn
    validate_repo_id(arg_value)
  File "C:\Users\Kiran Aradhya\anaconda3\envs\textS1\lib\site-packages\huggingface_hub\utils\_validators.py", line 158, in validate_repo_id
    raise HFValidationError(
huggingface_hub.utils._validators.HFValidationError: Repo id must be in the form 'repo_name' or 'namespace/repo_name': 'artifacts/model_trainer/tokenizer'. Use `repo_type` argument if needed.

The above exception was the direct cause of the following exception:

Traceback (most recent call last):
  File "C:\Users\Kiran Aradhya\anaconda3\envs\textS1\lib\site-packages\uvicorn\protocols\http\h11_impl.py", line 404, in run_asgi
    result = await app(  # type: ignore[func-returns-value]
  File "C:\Users\Kiran Aradhya\anaconda3\envs\textS1\lib\site-packages\uvicorn\middleware\proxy_headers.py", line 78, in __call__
    return await self.app(scope, receive, send)
  File "C:\Users\Kiran Aradhya\anaconda3\envs\textS1\lib\site-packages\fastapi\applications.py", line 269, in __call__
    await super().__call__(scope, receive, send)
  File "C:\Users\Kiran Aradhya\anaconda3\envs\textS1\lib\site-packages\starlette\applications.py", line 124, in __call__
    await self.middleware_stack(scope, receive, send)
  File "C:\Users\Kiran Aradhya\anaconda3\envs\textS1\lib\site-packages\starlette\middleware\errors.py", line 184, in __call__
    raise exc
  File "C:\Users\Kiran Aradhya\anaconda3\envs\textS1\lib\site-packages\starlette\middleware\errors.py", line 162, in __call__
    await self.app(scope, receive, _send)
  File "C:\Users\Kiran Aradhya\anaconda3\envs\textS1\lib\site-packages\starlette\exceptions.py", line 93, in __call__
    raise exc
  File "C:\Users\Kiran Aradhya\anaconda3\envs\textS1\lib\site-packages\starlette\exceptions.py", line 82, in __call__
    await self.app(scope, receive, sender)
  File "C:\Users\Kiran Aradhya\anaconda3\envs\textS1\lib\site-packages\fastapi\middleware\asyncexitstack.py", line 21, in __call__
    raise e
  File "C:\Users\Kiran Aradhya\anaconda3\envs\textS1\lib\site-packages\fastapi\middleware\asyncexitstack.py", line 18, in __call__
    await self.app(scope, receive, send)
  File "C:\Users\Kiran Aradhya\anaconda3\envs\textS1\lib\site-packages\starlette\routing.py", line 670, in __call__
    await route.handle(scope, receive, send)
  File "C:\Users\Kiran Aradhya\anaconda3\envs\textS1\lib\site-packages\starlette\routing.py", line 266, in handle
    await self.app(scope, receive, send)
  File "C:\Users\Kiran Aradhya\anaconda3\envs\textS1\lib\site-packages\starlette\routing.py", line 65, in app
    response = await func(request)
  File "C:\Users\Kiran Aradhya\anaconda3\envs\textS1\lib\site-packages\fastapi\routing.py", line 227, in app
    raw_response = await run_endpoint_function(
  File "C:\Users\Kiran Aradhya\anaconda3\envs\textS1\lib\site-packages\fastapi\routing.py", line 160, in run_endpoint_function
    return await dependant.call(**values)
  File "app.py", line 41, in predict_route
    raise e
  File "app.py", line 38, in predict_route
    text = obj.predict(text)
  File "d:\text-summarizer-project\src\textSummarizer\pipeline\prediction.py", line 13, in predict
    tokenizer = AutoTokenizer.from_pretrained(self.config.tokenizer_path)
  File "C:\Users\Kiran Aradhya\anaconda3\envs\textS1\lib\site-packages\transformers\models\auto\tokenization_auto.py", line 737, in from_pretrained
    tokenizer_config = get_tokenizer_config(pretrained_model_name_or_path, **kwargs)
  File "C:\Users\Kiran Aradhya\anaconda3\envs\textS1\lib\site-packages\transformers\models\auto\tokenization_auto.py", line 569, in get_tokenizer_config
    resolved_config_file = cached_file(
  File "C:\Users\Kiran Aradhya\anaconda3\envs\textS1\lib\site-packages\transformers\utils\hub.py", line 454, in cached_file
    raise EnvironmentError(
OSError: Incorrect path_or_model_id: 'artifacts/model_trainer/tokenizer'. Please provide either the path to a local folder or the repo_id of a model on the Hub.
[2024-01-02 12:57:18,848: INFO: common: yaml file: config\config.yaml loaded successfully]
[2024-01-02 12:57:18,850: INFO: common: yaml file: params.yaml loaded successfully]
[2024-01-02 12:57:18,850: INFO: common: created directory at: artifacts]
[2024-01-02 12:57:18,851: INFO: common: created directory at: artifacts/model_evaluation]
[2024-01-02 12:57:18,854: ERROR: h11_impl: Exception in ASGI application
]
Traceback (most recent call last):
  File "C:\Users\Kiran Aradhya\anaconda3\envs\textS1\lib\site-packages\transformers\utils\hub.py", line 389, in cached_file
    resolved_file = hf_hub_download(
  File "C:\Users\Kiran Aradhya\anaconda3\envs\textS1\lib\site-packages\huggingface_hub\utils\_validators.py", line 110, in _inner_fn
    validate_repo_id(arg_value)
  File "C:\Users\Kiran Aradhya\anaconda3\envs\textS1\lib\site-packages\huggingface_hub\utils\_validators.py", line 158, in validate_repo_id
    raise HFValidationError(
huggingface_hub.utils._validators.HFValidationError: Repo id must be in the form 'repo_name' or 'namespace/repo_name': 'artifacts/model_trainer/tokenizer'. Use `repo_type` argument if needed.

The above exception was the direct cause of the following exception:

Traceback (most recent call last):
  File "C:\Users\Kiran Aradhya\anaconda3\envs\textS1\lib\site-packages\uvicorn\protocols\http\h11_impl.py", line 404, in run_asgi
    result = await app(  # type: ignore[func-returns-value]
  File "C:\Users\Kiran Aradhya\anaconda3\envs\textS1\lib\site-packages\uvicorn\middleware\proxy_headers.py", line 78, in __call__
    return await self.app(scope, receive, send)
  File "C:\Users\Kiran Aradhya\anaconda3\envs\textS1\lib\site-packages\fastapi\applications.py", line 269, in __call__
    await super().__call__(scope, receive, send)
  File "C:\Users\Kiran Aradhya\anaconda3\envs\textS1\lib\site-packages\starlette\applications.py", line 124, in __call__
    await self.middleware_stack(scope, receive, send)
  File "C:\Users\Kiran Aradhya\anaconda3\envs\textS1\lib\site-packages\starlette\middleware\errors.py", line 184, in __call__
    raise exc
  File "C:\Users\Kiran Aradhya\anaconda3\envs\textS1\lib\site-packages\starlette\middleware\errors.py", line 162, in __call__
    await self.app(scope, receive, _send)
  File "C:\Users\Kiran Aradhya\anaconda3\envs\textS1\lib\site-packages\starlette\exceptions.py", line 93, in __call__
    raise exc
  File "C:\Users\Kiran Aradhya\anaconda3\envs\textS1\lib\site-packages\starlette\exceptions.py", line 82, in __call__
    await self.app(scope, receive, sender)
  File "C:\Users\Kiran Aradhya\anaconda3\envs\textS1\lib\site-packages\fastapi\middleware\asyncexitstack.py", line 21, in __call__
    raise e
  File "C:\Users\Kiran Aradhya\anaconda3\envs\textS1\lib\site-packages\fastapi\middleware\asyncexitstack.py", line 18, in __call__
    await self.app(scope, receive, send)
  File "C:\Users\Kiran Aradhya\anaconda3\envs\textS1\lib\site-packages\starlette\routing.py", line 670, in __call__
    await route.handle(scope, receive, send)
  File "C:\Users\Kiran Aradhya\anaconda3\envs\textS1\lib\site-packages\starlette\routing.py", line 266, in handle
    await self.app(scope, receive, send)
  File "C:\Users\Kiran Aradhya\anaconda3\envs\textS1\lib\site-packages\starlette\routing.py", line 65, in app
    response = await func(request)
  File "C:\Users\Kiran Aradhya\anaconda3\envs\textS1\lib\site-packages\fastapi\routing.py", line 227, in app
    raw_response = await run_endpoint_function(
  File "C:\Users\Kiran Aradhya\anaconda3\envs\textS1\lib\site-packages\fastapi\routing.py", line 160, in run_endpoint_function
    return await dependant.call(**values)
  File "app.py", line 41, in predict_route
    raise e
  File "app.py", line 38, in predict_route
    text = obj.predict(text)
  File "d:\text-summarizer-project\src\textSummarizer\pipeline\prediction.py", line 13, in predict
    tokenizer = AutoTokenizer.from_pretrained(self.config.tokenizer_path)
  File "C:\Users\Kiran Aradhya\anaconda3\envs\textS1\lib\site-packages\transformers\models\auto\tokenization_auto.py", line 737, in from_pretrained
    tokenizer_config = get_tokenizer_config(pretrained_model_name_or_path, **kwargs)
  File "C:\Users\Kiran Aradhya\anaconda3\envs\textS1\lib\site-packages\transformers\models\auto\tokenization_auto.py", line 569, in get_tokenizer_config
    resolved_config_file = cached_file(
  File "C:\Users\Kiran Aradhya\anaconda3\envs\textS1\lib\site-packages\transformers\utils\hub.py", line 454, in cached_file
    raise EnvironmentError(
OSError: Incorrect path_or_model_id: 'artifacts/model_trainer/tokenizer'. Please provide either the path to a local folder or the repo_id of a model on the Hub.
[2024-01-02 12:57:38,272: INFO: server: Shutting down]
[2024-01-02 12:57:38,382: INFO: on: Waiting for application shutdown.]
[2024-01-02 12:57:38,385: INFO: on: Application shutdown complete.]
[2024-01-02 12:57:38,387: INFO: server: Finished server process [17036]]
[2024-01-02 12:58:21,721: INFO: config: PyTorch version 2.1.2 available.]
[2024-01-02 12:58:22,660: INFO: main: >>>>>> stage Data Ingestion stage started <<<<<<]
[2024-01-02 12:58:22,663: INFO: common: yaml file: config\config.yaml loaded successfully]
[2024-01-02 12:58:22,665: INFO: common: yaml file: params.yaml loaded successfully]
[2024-01-02 12:58:22,665: INFO: common: created directory at: artifacts]
[2024-01-02 12:58:22,666: INFO: common: created directory at: artifacts/data_ingestion]
[2024-01-02 12:58:22,666: INFO: data_ingestion: Downloading data from https://github.com/entbappy/Branching-tutorial/raw/master/summarizer-data.zip into file artifacts/data_ingestion/data.zip]
[2024-01-02 12:58:23,281: INFO: data_ingestion: Downloaded data from https://github.com/entbappy/Branching-tutorial/raw/master/summarizer-data.zip into file artifacts/data_ingestion/data.zip]
[2024-01-02 12:58:23,370: INFO: main: >>>>>> stage Data Ingestion stage completed <<<<<<

x==========x]
[2024-01-02 12:58:23,371: INFO: main: >>>>>> stage Data Validation stage started <<<<<<]
[2024-01-02 12:58:23,374: INFO: common: yaml file: config\config.yaml loaded successfully]
[2024-01-02 12:58:23,376: INFO: common: yaml file: params.yaml loaded successfully]
[2024-01-02 12:58:23,376: INFO: common: created directory at: artifacts]
[2024-01-02 12:58:23,377: INFO: common: created directory at: artifacts/data_validation]
[2024-01-02 12:58:23,377: ERROR: main: [WinError 3] The system cannot find the path specified: 'artifacts\\data_ingestion\\samsun\\samsum_dataset']
Traceback (most recent call last):
  File "main.py", line 26, in <module>
    data_validation.main()
  File "d:\text-summarizer-project\src\textSummarizer\pipeline\stage_02_data_validation.py", line 14, in main
    data_validation.validate_all_files_exist()
  File "d:\text-summarizer-project\src\textSummarizer\conponents\data_validation.py", line 30, in validate_all_files_exist
    raise e
  File "d:\text-summarizer-project\src\textSummarizer\conponents\data_validation.py", line 15, in validate_all_files_exist
    all_files = os.listdir(os.path.join("artifacts","data_ingestion","samsun","samsum_dataset"))
FileNotFoundError: [WinError 3] The system cannot find the path specified: 'artifacts\\data_ingestion\\samsun\\samsum_dataset'
[2024-01-02 12:59:02,469: INFO: config: PyTorch version 2.1.2 available.]
[2024-01-02 12:59:03,556: INFO: main: >>>>>> stage Data Ingestion stage started <<<<<<]
[2024-01-02 12:59:03,559: INFO: common: yaml file: config\config.yaml loaded successfully]
[2024-01-02 12:59:03,560: INFO: common: yaml file: params.yaml loaded successfully]
[2024-01-02 12:59:03,561: INFO: common: created directory at: artifacts]
[2024-01-02 12:59:03,562: INFO: common: created directory at: artifacts/data_ingestion]
[2024-01-02 12:59:03,562: INFO: data_ingestion: Downloading data from https://github.com/entbappy/Branching-tutorial/raw/master/summarizer-data.zip into file artifacts/data_ingestion/data.zip]
[2024-01-02 12:59:04,149: INFO: data_ingestion: Downloaded data from https://github.com/entbappy/Branching-tutorial/raw/master/summarizer-data.zip into file artifacts/data_ingestion/data.zip]
[2024-01-02 12:59:04,244: INFO: main: >>>>>> stage Data Ingestion stage completed <<<<<<

x==========x]
[2024-01-02 12:59:04,245: INFO: main: >>>>>> stage Data Validation stage started <<<<<<]
[2024-01-02 12:59:04,248: INFO: common: yaml file: config\config.yaml loaded successfully]
[2024-01-02 12:59:04,249: INFO: common: yaml file: params.yaml loaded successfully]
[2024-01-02 12:59:04,250: INFO: common: created directory at: artifacts]
[2024-01-02 12:59:04,251: INFO: common: created directory at: artifacts/data_validation]
[2024-01-02 12:59:04,252: INFO: main: >>>>>> stage Data Validation stage completed <<<<<<

x==========x]
[2024-01-02 12:59:04,252: INFO: main: >>>>>> stage Data Transformation stage started <<<<<<]
[2024-01-02 12:59:04,255: INFO: common: yaml file: config\config.yaml loaded successfully]
[2024-01-02 12:59:04,257: INFO: common: yaml file: params.yaml loaded successfully]
[2024-01-02 12:59:04,258: INFO: common: created directory at: artifacts]
[2024-01-02 12:59:04,259: INFO: common: created directory at: artifacts/data_transformation]
[2024-01-02 12:59:07,891: INFO: main: >>>>>> stage Data Transformation stage completed <<<<<<

x==========x]
[2024-01-02 12:59:07,893: INFO: main: *******************]
[2024-01-02 12:59:07,893: INFO: main: >>>>>> stage Model Trainer stage started <<<<<<]
[2024-01-02 12:59:07,896: INFO: common: yaml file: config\config.yaml loaded successfully]
[2024-01-02 12:59:07,898: INFO: common: yaml file: params.yaml loaded successfully]
[2024-01-02 12:59:07,898: INFO: common: created directory at: artifacts]
[2024-01-02 12:59:07,899: INFO: common: created directory at: artifacts/model_trainer]
[2024-01-02 13:00:54,575: INFO: config: PyTorch version 2.1.2 available.]
[2024-01-02 13:00:55,811: INFO: main: >>>>>> stage Data Ingestion stage started <<<<<<]
[2024-01-02 13:00:55,813: INFO: common: yaml file: config\config.yaml loaded successfully]
[2024-01-02 13:00:55,817: INFO: common: yaml file: params.yaml loaded successfully]
[2024-01-02 13:00:55,817: INFO: common: created directory at: artifacts]
[2024-01-02 13:00:55,817: INFO: common: created directory at: artifacts/data_ingestion]
[2024-01-02 13:00:55,818: INFO: data_ingestion: Downloading data from https://github.com/entbappy/Branching-tutorial/raw/master/summarizer-data.zip into file artifacts/data_ingestion/data.zip]
[2024-01-02 13:00:56,545: INFO: data_ingestion: Downloaded data from https://github.com/entbappy/Branching-tutorial/raw/master/summarizer-data.zip into file artifacts/data_ingestion/data.zip]
[2024-01-02 13:00:56,637: INFO: main: >>>>>> stage Data Ingestion stage completed <<<<<<

x==========x]
[2024-01-02 13:00:56,638: INFO: main: >>>>>> stage Data Validation stage started <<<<<<]
[2024-01-02 13:00:56,641: INFO: common: yaml file: config\config.yaml loaded successfully]
[2024-01-02 13:00:56,643: INFO: common: yaml file: params.yaml loaded successfully]
[2024-01-02 13:00:56,643: INFO: common: created directory at: artifacts]
[2024-01-02 13:00:56,644: INFO: common: created directory at: artifacts/data_validation]
[2024-01-02 13:00:56,645: INFO: main: >>>>>> stage Data Validation stage completed <<<<<<

x==========x]
[2024-01-02 13:00:56,646: INFO: main: >>>>>> stage Data Transformation stage started <<<<<<]
[2024-01-02 13:00:56,649: INFO: common: yaml file: config\config.yaml loaded successfully]
[2024-01-02 13:00:56,651: INFO: common: yaml file: params.yaml loaded successfully]
[2024-01-02 13:00:56,652: INFO: common: created directory at: artifacts]
[2024-01-02 13:00:56,653: INFO: common: created directory at: artifacts/data_transformation]
[2024-01-02 13:00:58,106: INFO: main: >>>>>> stage Data Transformation stage completed <<<<<<

x==========x]
[2024-01-02 13:00:58,107: INFO: main: *******************]
[2024-01-02 13:00:58,107: INFO: main: >>>>>> stage Model Trainer stage started <<<<<<]
[2024-01-02 13:00:58,110: INFO: common: yaml file: config\config.yaml loaded successfully]
[2024-01-02 13:00:58,112: INFO: common: yaml file: params.yaml loaded successfully]
[2024-01-02 13:00:58,113: INFO: common: created directory at: artifacts]
[2024-01-02 13:00:58,113: INFO: common: created directory at: artifacts/model_trainer]
[2024-01-02 13:18:32,128: INFO: config: PyTorch version 2.1.2 available.]
[2024-01-02 13:18:36,836: INFO: common: yaml file: config\config.yaml loaded successfully]
[2024-01-02 13:18:36,842: INFO: common: yaml file: params.yaml loaded successfully]
[2024-01-02 13:18:36,844: INFO: common: created directory at: artifacts]
[2024-01-02 13:18:36,845: INFO: common: created directory at: artifacts/model_trainer]
[2024-01-02 13:20:31,006: INFO: config: PyTorch version 2.1.2 available.]
[2024-01-02 13:20:32,245: INFO: main: >>>>>> stage Data Ingestion stage started <<<<<<]
[2024-01-02 13:20:32,249: INFO: common: yaml file: config\config.yaml loaded successfully]
[2024-01-02 13:20:32,253: INFO: common: yaml file: params.yaml loaded successfully]
[2024-01-02 13:20:32,253: INFO: common: created directory at: artifacts]
[2024-01-02 13:20:32,253: INFO: common: created directory at: artifacts/data_ingestion]
[2024-01-02 13:20:32,253: INFO: data_ingestion: Downloading data from https://github.com/entbappy/Branching-tutorial/raw/master/summarizer-data.zip into file artifacts/data_ingestion/data.zip]
[2024-01-02 13:20:32,980: INFO: data_ingestion: Downloaded data from https://github.com/entbappy/Branching-tutorial/raw/master/summarizer-data.zip into file artifacts/data_ingestion/data.zip]
[2024-01-02 13:20:33,082: INFO: main: >>>>>> stage Data Ingestion stage completed <<<<<<

x==========x]
[2024-01-02 13:20:33,082: INFO: main: >>>>>> stage Data Validation stage started <<<<<<]
[2024-01-02 13:20:33,086: INFO: common: yaml file: config\config.yaml loaded successfully]
[2024-01-02 13:20:33,089: INFO: common: yaml file: params.yaml loaded successfully]
[2024-01-02 13:20:33,090: INFO: common: created directory at: artifacts]
[2024-01-02 13:20:33,091: INFO: common: created directory at: artifacts/data_validation]
[2024-01-02 13:20:33,092: INFO: main: >>>>>> stage Data Validation stage completed <<<<<<

x==========x]
[2024-01-02 13:20:33,092: INFO: main: >>>>>> stage Data Transformation stage started <<<<<<]
[2024-01-02 13:20:33,097: INFO: common: yaml file: config\config.yaml loaded successfully]
[2024-01-02 13:20:33,100: INFO: common: yaml file: params.yaml loaded successfully]
[2024-01-02 13:20:33,100: INFO: common: created directory at: artifacts]
[2024-01-02 13:20:33,101: INFO: common: created directory at: artifacts/data_transformation]
[2024-01-02 13:20:34,523: INFO: main: >>>>>> stage Data Transformation stage completed <<<<<<

x==========x]
[2024-01-02 13:20:34,524: INFO: main: *******************]
[2024-01-02 13:20:34,524: INFO: main: >>>>>> stage Model Trainer stage started <<<<<<]
[2024-01-02 13:20:34,527: INFO: common: yaml file: config\config.yaml loaded successfully]
[2024-01-02 13:20:34,529: INFO: common: yaml file: params.yaml loaded successfully]
[2024-01-02 13:20:34,529: INFO: common: created directory at: artifacts]
[2024-01-02 13:20:34,530: INFO: common: created directory at: artifacts/model_trainer]
[2024-01-02 13:25:41,941: INFO: config: PyTorch version 2.1.2 available.]
[2024-01-02 13:25:44,472: INFO: common: yaml file: config\config.yaml loaded successfully]
[2024-01-02 13:25:44,475: INFO: common: yaml file: params.yaml loaded successfully]
[2024-01-02 13:25:44,477: INFO: common: created directory at: artifacts]
[2024-01-02 13:25:44,479: INFO: common: created directory at: artifacts/data_transformation]
[2024-01-02 13:32:54,395: INFO: config: PyTorch version 2.1.2 available.]
[2024-01-02 13:32:58,438: INFO: common: yaml file: config\config.yaml loaded successfully]
[2024-01-02 13:32:58,441: INFO: common: yaml file: params.yaml loaded successfully]
[2024-01-02 13:32:58,443: INFO: common: created directory at: artifacts]
[2024-01-02 13:32:58,444: INFO: common: created directory at: artifacts/model_trainer]
[2024-01-02 14:03:18,397: INFO: server: Started server process [15840]]
[2024-01-02 14:03:18,399: INFO: on: Waiting for application startup.]
[2024-01-02 14:03:18,399: INFO: on: Application startup complete.]
[2024-01-02 14:03:18,400: INFO: server: Uvicorn running on http://0.0.0.0:8080 (Press CTRL+C to quit)]
[2024-01-02 14:03:58,896: INFO: common: yaml file: config\config.yaml loaded successfully]
[2024-01-02 14:03:58,901: INFO: common: yaml file: params.yaml loaded successfully]
[2024-01-02 14:03:58,902: INFO: common: created directory at: artifacts]
[2024-01-02 14:03:58,903: INFO: common: created directory at: artifacts/model_evaluation]
[2024-01-02 14:04:59,936: INFO: server: Shutting down]
[2024-01-02 14:05:00,045: INFO: on: Waiting for application shutdown.]
[2024-01-02 14:05:00,046: INFO: on: Application shutdown complete.]
[2024-01-02 14:05:00,047: INFO: server: Finished server process [15840]]
[2024-01-02 14:06:06,996: INFO: config: PyTorch version 2.1.2 available.]
[2024-01-02 14:06:10,100: INFO: common: yaml file: config\config.yaml loaded successfully]
[2024-01-02 14:06:10,103: INFO: common: yaml file: params.yaml loaded successfully]
[2024-01-02 14:06:10,104: INFO: common: created directory at: artifacts]
[2024-01-02 14:06:10,106: INFO: common: created directory at: artifacts/model_evaluation]
[2024-01-02 14:09:09,702: WARNING: load: Using the latest cached version of the module from C:\Users\Kiran Aradhya\.cache\huggingface\modules\datasets_modules\metrics\rouge\08e5f021b5761265deaafbf424e57913106427f546189fe3f934069dd32c153f (last modified on Sat Dec 30 23:03:28 2023) since it couldn't be found locally at rouge, or remotely on the Hugging Face Hub.]
[2024-01-02 14:11:12,417: INFO: rouge_scorer: Using default tokenizer.]
[2024-01-02 14:12:02,442: INFO: common: yaml file: config\config.yaml loaded successfully]
[2024-01-02 14:12:02,445: INFO: common: yaml file: params.yaml loaded successfully]
[2024-01-02 14:12:02,447: INFO: common: created directory at: artifacts]
[2024-01-02 14:12:02,449: INFO: common: created directory at: artifacts/model_evaluation]
[2024-01-02 14:15:01,303: WARNING: load: Using the latest cached version of the module from C:\Users\Kiran Aradhya\.cache\huggingface\modules\datasets_modules\metrics\rouge\08e5f021b5761265deaafbf424e57913106427f546189fe3f934069dd32c153f (last modified on Sat Dec 30 23:03:28 2023) since it couldn't be found locally at rouge, or remotely on the Hugging Face Hub.]
[2024-01-02 14:17:01,620: INFO: rouge_scorer: Using default tokenizer.]
[2024-01-02 17:54:22,332: INFO: config: PyTorch version 2.1.2 available.]
[2024-01-02 17:54:24,443: INFO: common: yaml file: config\config.yaml loaded successfully]
[2024-01-02 17:54:24,461: INFO: common: yaml file: params.yaml loaded successfully]
[2024-01-02 17:54:24,463: INFO: common: created directory at: artifacts]
[2024-01-02 17:54:24,465: INFO: common: created directory at: artifacts/model_evaluation]
[2024-01-02 17:57:25,771: WARNING: load: Using the latest cached version of the module from C:\Users\Kiran Aradhya\.cache\huggingface\modules\datasets_modules\metrics\rouge\08e5f021b5761265deaafbf424e57913106427f546189fe3f934069dd32c153f (last modified on Sat Dec 30 23:03:28 2023) since it couldn't be found locally at rouge, or remotely on the Hugging Face Hub.]
[2024-01-02 17:59:35,224: INFO: rouge_scorer: Using default tokenizer.]
[2024-01-02 18:49:37,742: INFO: common: yaml file: config\config.yaml loaded successfully]
[2024-01-02 18:49:37,745: INFO: common: yaml file: params.yaml loaded successfully]
[2024-01-02 18:49:37,747: INFO: common: created directory at: artifacts]
[2024-01-02 18:49:37,749: INFO: common: created directory at: artifacts/model_evaluation]
[2024-01-02 18:52:36,968: WARNING: load: Using the latest cached version of the module from C:\Users\Kiran Aradhya\.cache\huggingface\modules\datasets_modules\metrics\rouge\08e5f021b5761265deaafbf424e57913106427f546189fe3f934069dd32c153f (last modified on Sat Dec 30 23:03:28 2023) since it couldn't be found locally at rouge, or remotely on the Hugging Face Hub.]
[2024-01-02 18:54:47,461: INFO: rouge_scorer: Using default tokenizer.]
[2024-01-02 19:01:28,765: INFO: common: yaml file: config\config.yaml loaded successfully]
[2024-01-02 19:01:28,768: INFO: common: yaml file: params.yaml loaded successfully]
[2024-01-02 19:01:28,770: INFO: common: created directory at: artifacts]
[2024-01-02 19:01:28,771: INFO: common: created directory at: artifacts/model_evaluation]
[2024-01-02 19:04:28,029: WARNING: load: Using the latest cached version of the module from C:\Users\Kiran Aradhya\.cache\huggingface\modules\datasets_modules\metrics\rouge\08e5f021b5761265deaafbf424e57913106427f546189fe3f934069dd32c153f (last modified on Sat Dec 30 23:03:28 2023) since it couldn't be found locally at rouge, or remotely on the Hugging Face Hub.]
[2024-01-02 19:06:37,135: INFO: rouge_scorer: Using default tokenizer.]
[2024-01-02 19:23:31,825: INFO: common: yaml file: config\config.yaml loaded successfully]
[2024-01-02 19:23:31,829: INFO: common: yaml file: params.yaml loaded successfully]
[2024-01-02 19:23:31,830: INFO: common: created directory at: artifacts]
[2024-01-02 19:23:31,832: INFO: common: created directory at: artifacts/model_evaluation]
[2024-01-02 19:26:30,453: WARNING: load: Using the latest cached version of the module from C:\Users\Kiran Aradhya\.cache\huggingface\modules\datasets_modules\metrics\rouge\08e5f021b5761265deaafbf424e57913106427f546189fe3f934069dd32c153f (last modified on Sat Dec 30 23:03:28 2023) since it couldn't be found locally at rouge, or remotely on the Hugging Face Hub.]
[2024-01-02 19:28:40,493: INFO: rouge_scorer: Using default tokenizer.]
[2024-01-02 19:37:01,098: INFO: common: yaml file: config\config.yaml loaded successfully]
[2024-01-02 19:37:01,102: INFO: common: yaml file: params.yaml loaded successfully]
[2024-01-02 19:37:01,105: INFO: common: created directory at: artifacts]
[2024-01-02 19:37:01,106: INFO: common: created directory at: artifacts/model_evaluation]
[2024-01-02 19:40:00,813: WARNING: load: Using the latest cached version of the module from C:\Users\Kiran Aradhya\.cache\huggingface\modules\datasets_modules\metrics\rouge\08e5f021b5761265deaafbf424e57913106427f546189fe3f934069dd32c153f (last modified on Sat Dec 30 23:03:28 2023) since it couldn't be found locally at rouge, or remotely on the Hugging Face Hub.]
[2024-01-02 19:42:10,881: INFO: rouge_scorer: Using default tokenizer.]
[2024-01-02 22:58:25,891: INFO: config: PyTorch version 2.1.2 available.]
[2024-01-02 22:58:25,894: INFO: config: TensorFlow version 2.13.0 available.]
[2024-01-02 22:58:28,010: INFO: common: yaml file: config\config.yaml loaded successfully]
[2024-01-02 22:58:28,024: INFO: common: yaml file: params.yaml loaded successfully]
[2024-01-02 22:58:28,026: INFO: common: created directory at: artifacts]
[2024-01-02 22:58:28,027: INFO: common: created directory at: artifacts/model_evaluation]
[2024-01-02 23:01:27,973: WARNING: load: Using the latest cached version of the module from C:\Users\Kiran Aradhya\.cache\huggingface\modules\datasets_modules\metrics\rouge\08e5f021b5761265deaafbf424e57913106427f546189fe3f934069dd32c153f (last modified on Sat Dec 30 23:03:28 2023) since it couldn't be found locally at rouge, or remotely on the Hugging Face Hub.]
[2024-01-02 23:08:06,406: INFO: rouge_scorer: Using default tokenizer.]
[2024-01-03 09:02:24,307: INFO: config: PyTorch version 2.1.2 available.]
[2024-01-03 09:02:24,311: INFO: config: TensorFlow version 2.13.0 available.]
